<?xml version="1.0" encoding="utf-8"?>
<!-- This URDF was automatically created by SolidWorks to URDF Exporter! Originally created by Stephen Brawner (brawner@gmail.com) 
     Commit Version: 1.6.0-4-g7f85cfe  Build Version: 1.6.7995.38578
     For more information, please see http://wiki.ros.org/sw_urdf_exporter -->
<robot
  name="mybot">
  <link
    name="base_link">
    <inertial>
      <origin
        xyz="0.0602709488473398 0.144158022556777 0.185058903823586"
        rpy="0 0 0" />
      <mass
        value="0.466929101148318" />
      <inertia
        ixx="0.00183089444256355"
        ixy="4.05101806684342E-07"
        ixz="1.09593862371939E-05"
        iyy="0.00181811654011815"
        iyz="1.39749864395947E-05"
        izz="0.00198529296777552" />
    </inertial>
    <visual>
      <origin
        xyz="0 0 0"
        rpy="0 0 0" />
      <geometry>
        <mesh
          filename="package://mybot/meshes/base_link.STL" />
      </geometry>
      <material
        name="">
        <color
          rgba="0.792156862745098 0.819607843137255 0.933333333333333 1" />
      </material>
    </visual>
    <collision>
      <origin
        xyz="0 0 0"
        rpy="0 0 0" />
      <geometry>
        <mesh
          filename="package://mybot/meshes/base_link.STL" />
      </geometry>
    </collision>
  </link>
  <link
    name="1Link">
    <inertial>
      <origin
        xyz="4.47045456208883E-11 8.17671241934437E-06 -0.0358037441768474"
        rpy="0 0 0" />
      <mass
        value="0.0147886905275021" />
      <inertia
        ixx="1.04119911352484E-06"
        ixy="2.10981936411372E-15"
        ixz="3.37244906580305E-15"
        iyy="1.0419471020661E-06"
        iyz="8.04059074996839E-10"
        izz="1.7100066719771E-06" />
    </inertial>
    <visual>
      <origin
        xyz="0 0 0"
        rpy="0 0 0" />
      <geometry>
        <mesh
          filename="package://mybot/meshes/1Link.STL" />
      </geometry>
      <material
        name="">
        <color
          rgba="0.796078431372549 0.823529411764706 0.937254901960784 1" />
      </material>
    </visual>
    <collision>
      <origin
        xyz="0 0 0"
        rpy="0 0 0" />
      <geometry>
        <mesh
          filename="package://mybot/meshes/1Link.STL" />
      </geometry>
    </collision>
  </link>
  <joint
    name="W1"
    type="continuous">
    <origin
      xyz="-0.050661 -0.16348 0.079272"
      rpy="2.1066 -0.20312 -1.69" />
    <parent
      link="base_link" />
    <child
      link="1Link" />
    <axis
      xyz="0 0 1" />
    <limit
      lower="0"
      upper="0"
      effort="0"
      velocity="0" />
  </joint>
  <link
    name="2Link">
    <inertial>
      <origin
        xyz="3.25559579295032E-11 8.17688159190227E-06 0.00842976598063649"
        rpy="0 0 0" />
      <mass
        value="0.0147886899962811" />
      <inertia
        ixx="1.04119911054896E-06"
        ixy="1.40655384839249E-15"
        ixz="2.75934395229218E-15"
        iyy="1.0419471135416E-06"
        iyz="8.04056832387737E-10"
        izz="1.7100066587219E-06" />
    </inertial>
    <visual>
      <origin
        xyz="0 0 0"
        rpy="0 0 0" />
      <geometry>
        <mesh
          filename="package://mybot/meshes/2Link.STL" />
      </geometry>
      <material
        name="">
        <color
          rgba="0.796078431372549 0.823529411764706 0.937254901960784 1" />
      </material>
    </visual>
    <collision>
      <origin
        xyz="0 0 0"
        rpy="0 0 0" />
      <geometry>
        <mesh
          filename="package://mybot/meshes/2Link.STL" />
      </geometry>
    </collision>
  </link>
  <joint
    name="W2"
    type="continuous">
    <origin
      xyz="0.060682 -0.16348 0.22789"
      rpy="0 0 -0.87293" />
    <parent
      link="base_link" />
    <child
      link="2Link" />
    <axis
      xyz="0 0 1" />
    <limit
      lower="0"
      upper="0"
      effort="0"
      velocity="0" />
  </joint>
  <link
    name="3Link">
    <inertial>
      <origin
        xyz="4.47060582997594E-11 8.17671241962192E-06 0.00467976602749681"
        rpy="0 0 0" />
      <mass
        value="0.0147886905275021" />
      <inertia
        ixx="1.04119911352484E-06"
        ixy="2.10981933764394E-15"
        ixz="3.37244840660673E-15"
        iyy="1.0419471020661E-06"
        iyz="8.04059074997111E-10"
        izz="1.7100066719771E-06" />
    </inertial>
    <visual>
      <origin
        xyz="0 0 0"
        rpy="0 0 0" />
      <geometry>
        <mesh
          filename="package://mybot/meshes/3Link.STL" />
      </geometry>
      <material
        name="">
        <color
          rgba="0.796078431372549 0.823529411764706 0.937254901960784 1" />
      </material>
    </visual>
    <collision>
      <origin
        xyz="0 0 0"
        rpy="0 0 0" />
      <geometry>
        <mesh
          filename="package://mybot/meshes/3Link.STL" />
      </geometry>
    </collision>
  </link>
  <joint
    name="W3"
    type="continuous">
    <origin
      xyz="0.13697 -0.16348 0.099514"
      rpy="2.8467 -1.021 0.34221" />
    <parent
      link="base_link" />
    <child
      link="3Link" />
    <axis
      xyz="0 0 1" />
    <limit
      lower="0"
      upper="0"
      effort="0"
      velocity="0" />
  </joint>
  <link
    name="4Link">
    <inertial>
      <origin
        xyz="0 0 -0.0336941"
        rpy="0 0 0" />
      <mass
        value="0.0451206375403221" />
      <inertia
        ixx="1.78611798358203E-05"
        ixy="0"
        ixz="5.50988136138283E-22"
        iyy="1.78611798358203E-05"
        iyz="1.43039888619215E-23"
        izz="5.04465579675033E-06" />
    </inertial>
    <visual>
      <origin
        xyz="0 0 0"
        rpy="0 0 0" />
      <geometry>
        <mesh
          filename="package://mybot/meshes/4Link.STL" />
      </geometry>
      <material
        name="">
        <color
          rgba="0.792156862745098 0.819607843137255 0.933333333333333 1" />
      </material>
    </visual>
    <collision>
      <origin
        xyz="0 0 0"
        rpy="0 0 0" />
      <geometry>
        <mesh
          filename="package://mybot/meshes/4Link.STL" />
      </geometry>
    </collision>
  </link>
  <joint
    name="D4"
    type="continuous">
    <origin
      xyz="0.026988 -0.20848 0.052978"
      rpy="1.5708 0.28985 -1.5708" />
    <parent
      link="base_link" />
    <child
      link="4Link" />
    <axis
      xyz="0 0 1" />
    <limit
      lower="0"
      upper="0"
      effort="0"
      velocity="0" />
  </joint>
  <link
    name="5Link">
    <inertial>
      <origin
        xyz="0 0 -0.0273187311178248"
        rpy="0 0 0" />
      <mass
        value="0.00415946867335289" />
      <inertia
        ixx="7.00672811498495E-06"
        ixy="0"
        ixz="-2.37612402208306E-21"
        iyy="7.00672811498495E-06"
        iyz="1.23816930372388E-21"
        izz="5.05947213675328E-07" />
    </inertial>
    <visual>
      <origin
        xyz="0 0 0"
        rpy="0 0 0" />
      <geometry>
        <mesh
          filename="package://mybot/meshes/5Link.STL" />
      </geometry>
      <material
        name="">
        <color
          rgba="0.792156862745098 0.819607843137255 0.933333333333333 1" />
      </material>
    </visual>
    <collision>
      <origin
        xyz="0 0 0"
        rpy="0 0 0" />
      <geometry>
        <mesh
          filename="package://mybot/meshes/5Link.STL" />
      </geometry>
    </collision>
  </link>
  <joint
    name="K5"
    type="prismatic">
    <origin
      xyz="0.059096 -0.17048 0.052173"
      rpy="-3.1416 0 -2.0675" />
    <parent
      link="base_link" />
    <child
      link="5Link" />
    <axis
      xyz="0 0 1" />
    <limit
      lower="0"
      upper="0.03"
      effort="1"
      velocity="1" />
  </joint>
</robot>